<?xml version = "1.0"?>
<robot name = "camera" xmlns:xacro = "http://ros.org/wiki/xacro">

<xacro:arg name = "drone_height" default = "3" />

<material name="red">
  <color rgba="0.8 0 0 1"/> 
</material>

<link name = "world">
	<origin xyz = "0 0 0"/>
</link>

<joint name = "camera_joint" type = "floating">
	<parent link = "world"/>
	<child link = "drone_link"/>
	<origin xyz = "0 0 $(arg drone_height)" rpy = "0.0 ${pi / 2} ${pi / 2}"/>
</joint>

<link name = "drone_link">
    <collision>
      <origin xyz = "0 0 0" rpy = "0 0 0"/>
      <geometry>
    <box size="0.10 0.10 0.10"/>
      </geometry>
    </collision>

    <visual>
      <origin xyz = "0 0 0" rpy = "0 0 0"/>
      <geometry>
    <box size = "0.10 0.10 0.10"/>
      </geometry>
      <material name = "red"/>
    </visual>

    <inertial>
      <mass value = "1e-5" />
      <origin xyz = "0 0 0" rpy = "0 0 0"/>
      <inertia ixx = "1e-6" ixy = "0" ixz = "0" iyy = "1e-6" iyz = "0" izz = "1e-6" />
    </inertial>
  </link>

  <gazebo reference = "drone_link">
    <material>Gazebo/Red</material>
    <turnGravityOff>true</turnGravityOff> 	  
    <sensor type = "camera" name = "camera">
      <update_rate>30.0</update_rate>
      <camera name = "head">
        <horizontal_fov>1.3962634</horizontal_fov>
        <image>
          <width>800</width>
          <height>800</height>
          <format>R8G8B8</format>
        </image>
        <clip>
          <near>0.02</near>
          <far>300</far>
        </clip>
        <noise>
          <type>gaussian</type>
          <!-- Noise is sampled independently per pixel on each frame.
               That pixel's noise value is added to each of its color
               channels, which at that point lie in the range [0,1]. -->
          <mean>0.0</mean>
          <stddev>0.0</stddev>
        </noise>
      </camera>
      <plugin name = "camera_controller" filename = "libgazebo_ros_camera.so">
        <alwaysOn>true</alwaysOn>
        <updateRate>0.0</updateRate>
        <cameraName>camera</cameraName>
        <imageTopicName>image_raw</imageTopicName>
        <cameraInfoTopicName>camera_info</cameraInfoTopicName>
        <frameName>drone_link</frameName>
        <hackBaseline>0.07</hackBaseline>
        <distortionK1>0.0</distortionK1>
        <distortionK2>0.0</distortionK2>
        <distortionK3>0.0</distortionK3>
        <distortionT1>0.0</distortionT1>
        <distortionT2>0.0</distortionT2>
      </plugin>
    </sensor>
  </gazebo>
  <gazebo>
    <plugin name = "drone_controller" filename = "libgazebo_ros_planar_move.so">
        <commandTopic>cmd_vel</commandTopic>
        <odometryTopic>odom</odometryTopic>
        <odometryFrame>drone_odom</odometryFrame>
        <odometryRate>20.0</odometryRate>
        <robotBaseFrame>drone_link</robotBaseFrame>
      </plugin>
  </gazebo>
</robot>